Workbook

Sheet Reporte1_1
A1: SACHA CENTRAL | H1: PRODUCCION
A2: POZO | C2: FECHA | D2: CAMPO | F2: P. CAS | G2: HORAS | H2: BFPD | I2: BPPD | J2: BAPD | K2: MSCF | L2: BSW | M2: GOR | N2: T. | Q2: API | R2: FREC | S2: P. INY | T2: B. INY | U2: PSI | V2: PIP | W2: AMPERAJE | X2: VOL | Y2: SALIN. | Z2: TASA | AA2: BPPD | AB2: BAPD | AC2: MSCF | AD2: L.F. ESTACION | AE2: ESTACION
N3: BOMBA | U3: CABEZA
A4: SCH-013BT | C4: 45950 | D4: SACHA CENTRAL | F4: 0 | G4: 4 | H4: 385 | I4: 200 | J4: 185 | K4: 59.8 | L4: 48.05 | M4: 299 | N4: FLEX 7|FLEX 7|FLEX 7|FLEX 17.5 | Q4: 23.3 | R4: 53.4 | S4: 0 | T4: 0 | U4: 90 | V4: 285 | W4: 26 | X4: 426 | Y4: 25800 | Z4: 250 | AA4: 202.489 | AB4: 185 | AC4: 59.8 | AD4: 1.01244 | AE4: SACHA CENTRAL
A5: SCH-017U | C5: 45950 | D5: SACHA CENTRAL | F5: 70 | G5: 3 | H5: 372 | I5: 281 | J5: 91 | K5: 81.33 | L5: 24.32 | M5: 289 | N5: JET 11K | Q5: 24.4 | R5: 0 | S5: 0 | T5: 2477 | U5: 3750 | V5: 0 | W5: 0 | X5: 0 | Y5: 11900 | Z5: 700 | AA5: 284.497 | AB5: 91 | AC5: 81.33 | AD5: 1.01244 | AE5: SACHA CENTRAL
A6: SCH-018UI | C6: 45951 | D6: SACHA CENTRAL | F6: 0 | G6: 4 | H6: 1369 | I6: 356 | J6: 1013 | K6: 106.09 | L6: 74 | M6: 298 | N6: NH2100M|NH2100M|NH2100M|N406MPP940 | Q6: 25.1 | R6: 122 | S6: 0 | T6: 0 | U6: 90 | V6: 411 | W6: 33 | X6: 431 | Y6: 5200 | Z6: 450 | AA6: 360.43 | AB6: 1013 | AC6: 106.09 | AD6: 1.01244 | AE6: SACHA CENTRAL
A7: SCH-019U | C7: 45952 | D7: SACHA CENTRAL | F7: 0 | G7: 4 | H7: 432 | I7: 43 | J7: 389 | K7: 8.64 | L7: 90.05 | M7: 201 | N7: SF-320|SF-320|SF-900|SFGH2500 | Q7: 26.7 | R7: 65 | S7: 0 | T7: 0 | U7: 60 | V7: 428 | W7: 29 | X7: 479 | Y7: 13900 | Z7: 650 | AA7: 43.535 | AB7: 389 | AC7: 8.64 | AD7: 1.01244 | AE7: SACHA CENTRAL
A8: SCH-025U | C8: 45950 | D8: SACHA CENTRAL | F8: 70 | G8: 4 | H8: 654 | I8: 244 | J8: 410 | K8: 62.7 | L8: 62.71 | M8: 257 | N8: JET 11K | Q8: 25.6 | R8: 0 | S8: 0 | T8: 2185 | U8: 3850 | V8: 0 | W8: 0 | X8: 0 | Y8: 8000 | Z8: 400 | AA8: 247.036 | AB8: 410 | AC8: 62.7 | AD8: 1.01244 | AE8: SACHA CENTRAL
A9: SCH-037T | C9: 45952 | D9: SACHA CENTRAL | F9: 0 | G9: 3 | H9: 202 | I9: 158 | J9: 44 | K9: 47.24 | L9: 21.78 | M9: 299 | N9: NBV(160-250)H|NBV(160-250)H|NBV(160-250)H|NBV(160-250)H | Q9: 33.9 | R9: 144 | S9: 0 | T9: 0 | U9: 30 | V9: 366 | W9: 31 | X9: 389 | Y9: 14100 | Z9: 380 | AA9: 159.966 | AB9: 44 | AC9: 47.24 | AD9: 1.01244 | AE9: SACHA CENTRAL
A10: SCH-083HI | C10: 45946 | D10: SACHA CENTRAL | F10: 0 | G10: 4 | H10: 1702 | I10: 255 | J10: 1447 | K10: 2.04 | L10: 85.02 | M10: 8 | N10: FLEX7ER SSD|FLEX7ER SSD|FLEX7ER SSD|FLEX 17.5 | Q10: 27.7 | R10: 58 | S10: 0 | T10: 0 | U10: 100 | V10: 2232 | W10: 62 | X10: 426 | Y10: 1250 | Z10: 140 | AA10: 258.173 | AB10: 1447 | AC10: 2.04 | AD10: 1.01244 | AE10: SACHA CENTRAL
A11: SCH-087BT | C11: 45949 | D11: SACHA CENTRAL | F11: 0 | G11: 4 | H11: 1275 | I11: 204 | J11: 1071 | K11: 61 | L11: 84 | M11: 299 | N11: FLEX 17.5|FLEX 17.5|FLEX 17.5|FLEXER | Q11: 24 | R11: 59 | S11: 0 | T11: 0 | U11: 350 | V11: 332 | W11: 59 | X11: 412 | Y11: 9700 | Z11: 250 | AA11: 206.538 | AB11: 1071 | AC11: 61 | AD11: 1.01244 | AE11: SACHA CENTRAL
A12: SCH-088T | C12: 45940 | D12: SACHA CENTRAL | F12: 0 | G12: 3 | H12: 1189 | I12: 618 | J12: 571 | K12: 234.84 | L12: 48.02 | M12: 380 | N12: DN1750|DN1750|DN1750|DN1750 | Q12: 28.1 | R12: 60.5 | S12: 0 | T12: 0 | U12: 200 | V12: 298 | W12: 43 | X12: 444 | Y12: 12000 | Z12: 800 | AA12: 312.845 | AB12: 285.5 | AC12: 117.42 | AD12: 1.01244 | AE12: SACHA CENTRAL
A13: SCH-098U | C13: 45950 | D13: SACHA CENTRAL | F13: 0 | G13: 3 | H13: 359 | I13: 101 | J13: 258 | K13: 96.96 | L13: 71.87 | M13: 960 | N13: NH940M|NH940M|NH940M|N406MPP940 | Q13: 26.1 | R13: 49 | S13: 0 | T13: 0 | U13: 60 | V13: 157 | W13: 25 | X13: 385 | Y13: 11800 | Z13: 750 | AA13: 102.257 | AB13: 258 | AC13: 96.96 | AD13: 1.01244 | AE13: SACHA CENTRAL
A14: SCH-099TI | C14: 45950 | D14: SACHA CENTRAL | F14: 0 | G14: 4 | H14: 449 | I14: 314 | J14: 135 | K14: 157 | L14: 30.07 | M14: 500 | N14: NH940M|NH940M|NH940M | Q14: 30.4 | R14: 58 | S14: 0 | T14: 0 | U14: 150 | V14: 330 | W14: 27 | X14: 464 | Y14: 35800 | Z14: 800 | AA14: 317.907 | AB14: 135 | AC14: 157 | AD14: 1.01244 | AE14: SACHA CENTRAL
A15: SCH-101U | C15: 45952 | D15: SACHA CENTRAL | F15: 70 | G15: 4 | H15: 864 | I15: 274 | J15: 590 | K15: 55.6 | L15: 68.31 | M15: 203 | N15: JET 11J | Q15: 26.5 | R15: 0 | S15: 0 | T15: 2217 | U15: 3750 | V15: 0 | W15: 0 | X15: 0 | Y15: 6250 | Z15: 300 | AA15: 277.409 | AB15: 590 | AC15: 55.6 | AD15: 1.01244 | AE15: SACHA CENTRAL
... A45: SCHAP-488HUI | C45: 45946 | D45: SACHA CENTRAL | F45: 0 | G45: 4 | H45: 350 | I45: 343 | J45: 7 | K45: 66.89 | L45: 2 | M45: 195 | N45: FLEX 10|FLEX 10|FLEX 10|FLEX 17.5 | Q45: 18.2 | R45: 48.5 | S45: 0 | T45: 0 | U45: 70 | V45: 0 | W45: 28 | X45: 363 | Y45: 55500 | Z45: 600 | AA45: 347.268 | AB45: 7 | AC45: 66.89 | AD45: 1.01244 | AE45: SACHA CENTRAL
A46: TOTAL | D46: SACHA CENTRAL | H46: 30221 | I46: 13240 | J46: 16981 | K46: 4065.82 | M46: 307 | Z46: 27902 | AA46: 13091.903 | AB46: 16695.5 | AC46: 3948.4
A47: SACHA NORTE 1 | H47: PRODUCCION
A48: POZO | C48: FECHA | D48: CAMPO | F48: P. CAS | G48: HORAS | H48: BFPD | I48: BPPD | J48: BAPD | K48: MSCF | L48: BSW | M48: GOR | N48: T. | Q48: API | R48: FREC | S48: P. INY | T48: B. INY | U48: PSI | V48: PIP | W48: AMPERAJE | X48: VOL | Y48: SALIN. | Z48: TASA | AA48: BPPD | AB48: BAPD | AC48: MSCF | AD48: L.F. ESTACION | AE48: ESTACION
N49: BOMBA | U49: CABEZA
A50: SCH-007T | C50: 45948 | D50: SACHA NORTE 1 | F50: 0 | G50: 3 | H50: 49 | I50: 10 | J50: 39 | K50: 2.89 | L50: 79.59 | M50: 289 | N50: FLEXER|FLEXER|FLEXER | Q50: 22.4 | R50: 65 | S50: 0 | T50: 0 | U50: 450 | V50: 1011 | W50: 58 | X50: 459 | Y50: 10200 | Z50: 1400 | AA50: 10.124 | AB50: 39 | AC50: 2.89 | AD50: 1.01244 | AE50: SACHA CENTRAL
A51: SCH-007U | C51: 45948 | D51: SACHA NORTE 1 | F51: 0 | G51: 5 | H51: 1612 | I51: 322 | J51: 1290 | K51: 93.06 | L51: 80.03 | M51: 289 | N51: FLEXER|FLEXER|FLEXER | Q51: 22.6 | R51: 65 | S51: 0 | T51: 0 | U51: 450 | V51: 994 | W51: 58 | X51: 459 | Y51: 10200 | Z51: 1400 | AA51: 326.007 | AB51: 1290 | AC51: 93.06 | AD51: 1.01244 | AE51: SACHA CENTRAL
A52: SCH-031HS | C52: 45952 | D52: SACHA NORTE 1 | F52: 100 | G52: 4 | H52: 237 | I52: 199 | J52: 38 | K52: 30.05 | L52: 16.03 | M52: 151 | N52: FLEX 7ER|FLEX 7ER|FLEX 17.5 | Q52: 21 | R52: 58 | S52: 0 | T52: 0 | U52: 300 | V52: 218 | W52: 18 | X52: 464 | Y52: 9200 | Z52: 600 | AA52: 201.476 | AB52: 38 | AC52: 30.05 | AD52: 1.01244 | AE52: SACHA CENTRAL
A53: SCH-050UI | C53: 45951 | D53: SACHA NORTE 1 | F53: 0 | G53: 5 | H53: 2012 | I53: 96 | J53: 1916 | K53: 14.88 | L53: 95.23 | M53: 155 | N53: NH2100M|NH2100M|NH2100M | Q53: 24.3 | R53: 62 | S53: 0 | T53: 0 | U53: 150 | V53: 1427 | W53: 50 | X53: 438 | Y53: 18000 | Z53: 440 | AA53: 97.194 | AB53: 1916 | AC53: 14.88 | AD53: 1.01244 | AE53: SACHA CENTRAL
A54: SCH-051T | C54: 45946 | D54: SACHA NORTE 1 | F54: 0 | G54: 5 | H54: 251 | I54: 186 | J54: 65 | K54: 53.75 | L54: 25.9 | M54: 289 | N54: WD-600|WD-1000MF|WD-1000MF | Q54: 29.6 | R54: 55 | S54: 0 | T54: 0 | U54: 90 | V54: 212 | W54: 19 | X54: 424 | Y54: 39800 | Z54: 800 | AA54: 188.314 | AB54: 65 | AC54: 53.75 | AD54: 1.01244 | AE54: SACHA CENTRAL
A55: SCH-053U | C55: 45951 | D55: SACHA NORTE 1 | F55: 0 | G55: 5 | H55: 314 | I55: 311 | J55: 3 | K55: 63.13 | L55: 0.96 | M55: 203 | N55: D1050N|DN1750|DN1750|D5-21 | Q55: 21.2 | R55: 62 | S55: 0 | T55: 0 | U55: 680 | V55: 329 | W55: 25 | X55: 456 | Y55: 14500 | Z55: 600 | AA55: 314.87 | AB55: 3 | AC55: 63.13 | AD55: 1.01244 | AE55: SACHA CENTRAL
A56: SCH-096BT | C56: 45945 | D56: SACHA NORTE 1 | F56: 50 | G56: 5 | H56: 292 | I56: 175 | J56: 117 | K56: 35.53 | L56: 39.87 | M56: 203 | N56: JET 9I | Q56: 23.8 | R56: 0 | S56: 0 | T56: 1518 | U56: 3850 | V56: 0 | W56: 0 | X56: 0 | Y56: 31900 | Z56: 500 | AA56: 177.178 | AB56: 117 | AC56: 35.53 | AD56: 1.01244 | AE56: SACHA CENTRAL
A57: SCH-102U | C57: 45951 | D57: SACHA NORTE 1 | F57: 0 | G57: 5 | H57: 458 | I57: 165 | J57: 293 | K57: 25.58 | L57: 63.97 | M57: 155 | N57: TD-675|TD-675|TD-675 | Q57: 24.7 | R57: 61 | S57: 0 | T57: 0 | U57: 70 | V57: 0 | W57: 32 | X57: 427 | Y57: 6000 | Z57: 170 | AA57: 167.053 | AB57: 293 | AC57: 25.58 | AD57: 1.01244 | AE57: SACHA CENTRAL
A58: SCH-106HS | C58: 45952 | D58: SACHA NORTE 1 | F58: 0 | G58: 5 | H58: 3067 | I58: 701 | J58: 2366 | K58: 106.8 | L58: 77.14 | M58: 152 | N58: D3550N|D3550N|D3500N|D3550N|D20 | Q58: 26.8 | R58: 59.2 | S58: 0 | T58: 0 | U58: 180 | V58: 550 | W58: 70 | X58: 452 | Y58: 17100 | Z58: 900 | AA58: 709.723 | AB58: 2366 | AC58: 106.8 | AD58: 1.01244 | AE58: SACHA CENTRAL
A59: SCH-119HS | C59: 45949 | D59: SACHA NORTE 1 | F59: 50 | G59: 5 | H59: 211 | I59: 193 | J59: 18 | K59: 39 | L59: 8.48 | M59: 202 | N59: JET 11L | Q59: 26.9 | R59: 0 | S59: 0 | T59: 2520 | U59: 3700 | V59: 0 | W59: 0 | X59: 0 | Y59: 15500 | Z59: 500 | AA59: 195.401 | AB59: 18 | AC59: 39 | AD59: 1.01244 | AE59: SACHA CENTRAL
A60: SCH-127HS | C60: 45942 | D60: SACHA NORTE 1 | F60: 10 | G60: 5 | H60: 1838 | I60: 441 | J60: 1397 | K60: 66.59 | L60: 76.01 | M60: 151 | N60: DN1750|DN1750|DN1750 | Q60: 26.1 | R60: 55 | S60: 0 | T60: 0 | U60: 90 | V60: 0 | W60: 35 | X60: 434 | Y60: 1200 | Z60: 800 | AA60: 446.487 | AB60: 1397 | AC60: 66.59 | AD60: 1.01244 | AE60: SACHA CENTRAL
A61: SCHAN-460TI | C61: 45943 | D61: SACHA NORTE 1 | F61: 0 | G61: 4 | H61: 660 | I61: 198 | J61: 462 | K61: 57.22 | L61: 70 | M61: 289 | N61: E1000|E1000|E1000|FLEX 17.5 | Q61: 32.8 | R61: 51 | S61: 0 | T61: 0 | U61: 350 | V61: 491 | W61: 52 | X61: 409 | Y61: 13100 | Z61: 250 | AA61: 200.464 | AB61: 462 | AC61: 57.22 | AD61: 1.01244 | AE61: SACHA CENTRAL
... A77: SCHD-249HS | C77: 45943 | D77: SACHA NORTE 1 | F77: 0 | G77: 5 | H77: 479 | I77: 287 | J77: 192 | K77: 43.34 | L77: 40.08 | M77: 151 | N77: D1050N|DN1750|DN1750 | Q77: 25.8 | R77: 58 | S77: 0 | T77: 0 | U77: 190 | V77: 0 | W77: 28 | X77: 435 | Y77: 8500 | Z77: 460 | AA77: 290.571 | AB77: 192 | AC77: 43.34 | AD77: 1.01244 | AE77: SACHA CENTRAL
A78: SCHD-250HS | C78: 45935 | D78: SACHA NORTE 1 | F78: 50 | G78: 4 | H78: 545 | I78: 534 | J78: 11 | K78: 4.18 | L78: 2.02 | M78: 8 | N78: D1050N|DN1750|DN1750|D5-21 | Q78: 25.8 | R78: 51 | S78: 0 | T78: 0 | U78: 140 | V78: 950 | W78: 22 | X78: 382 | Y78: 14000 | AA78: 540.644 | AB78: 11 | AC78: 4.18 | AD78: 1.01244 | AE78: SACHA CENTRAL
A79: SCHD-253HS | C79: 45938 | D79: SACHA NORTE 1 | F79: 0 | G79: 5 | H79: 572 | I79: 446 | J79: 126 | K79: 9.76 | L79: 22.03 | M79: 22 | N79: E1000|E1000|E1000|FLEX 17.5 | Q79: 25.8 | R79: 46 | S79: 0 | T79: 0 | U79: 120 | V79: 1145 | W79: 24 | X79: 368 | Y79: 11000 | Z79: 700 | AA79: 451.55 | AB79: 126 | AC79: 9.76 | AD79: 1.01244 | AE79: SACHA CENTRAL
A80: SCHD-256TI | C80: 45950 | D80: SACHA NORTE 1 | F80: 0 | G80: 4 | H80: 987 | I80: 967 | J80: 20 | K80: 290.18 | L80: 2.03 | M80: 300 | N80: S1500N|S1500N|S1500N|S1500N | Q80: 30.3 | R80: 58 | S80: 0 | T80: 0 | U80: 150 | V80: 668 | W80: 30 | X80: 463 | Y80: 16000 | Z80: 800 | AA80: 979.033 | AB80: 20 | AC80: 290.18 | AD80: 1.01244 | AE80: SACHA CENTRAL
A81: SCHD-620HS | C81: 45949 | D81: SACHA NORTE 1 | F81: 40 | G81: 5 | H81: 330 | I81: 290 | J81: 40 | K81: 43.85 | L81: 12.12 | M81: 151 | N81: WD-3000|WD-3000|WD-3000|WD-3000 | Q81: 26.4 | R81: 52 | S81: 0 | T81: 0 | U81: 300 | V81: 558 | W81: 34 | X81: 389 | Y81: 14300 | AA81: 293.609 | AB81: 40 | AC81: 43.85 | AD81: 1.01244 | AE81: SACHA CENTRAL
A82: SCHD-623HS | C82: 45950 | D82: SACHA NORTE 1 | F82: 130 | G82: 5 | H82: 517 | I82: 486 | J82: 31 | K82: 73.38 | L82: 6 | M82: 151 | N82: NH940M|NH940M|NH940M | Q82: 26 | R82: 88 | S82: 0 | T82: 0 | U82: 250 | V82: 1155 | W82: 12.4 | X82: 331 | Y82: 8500 | Z82: 800 | AA82: 492.047 | AB82: 31 | AC82: 73.38 | AD82: 1.01244 | AE82: SACHA CENTRAL
A83: SCHF-247TI | C83: 45933 | D83: SACHA NORTE 1 | F83: 50 | G83: 4 | H83: 141 | I83: 130 | J83: 11 | K83: 37.57 | L83: 7.8 | M83: 289 | N83: RCXLF|RCXLF|RCXLF|RCXLF | Q83: 29.2 | R83: 58 | S83: 0 | T83: 0 | U83: 140 | V83: 200 | W83: 33 | X83: 435 | Y83: 41300 | Z83: 900 | AA83: 131.618 | AB83: 11 | AC83: 37.57 | AD83: 1.01244 | AE83: SACHA CENTRAL
A84: SCHN-163S1TI | C84: 45948 | D84: SACHA NORTE 1 | F84: 0 | G84: 5 | H84: 485 | I84: 427 | J84: 58 | K84: 123.4 | L84: 11.96 | M84: 289 | N84: E1000|E1000|FLEX 17.5 | Q84: 28.7 | R84: 59 | S84: 0 | T84: 0 | U84: 250 | V84: 204 | W84: 25 | X84: 473 | Y84: 24700 | Z84: 470 | AA84: 432.313 | AB84: 58 | AC84: 123.4 | AD84: 1.01244 | AE84: SACHA CENTRAL
...

Sheet POTENCIAL
A1: FECHA: | B1: Junio/3/2018
B3: BLANCA
A4: POZO | B4: FECHA | C4: BFPD | D4: BPPD | E4: BAPD | F4: MSCF | G4: BSW | H4: GOR | I4: T BOMBA | J4: API | K4: FREC | L4: PINY | M4: B INY | N4: PSI CAB | O4: PIP | P4: SALIN | Q4: TASA
A5: =IF(Reporte1_1!#REF!="","",Reporte1_1!#REF!) -> #REF! | B5: =IF(Reporte1_1!#REF!="","",Reporte1_1!#REF!) -> #REF! | C5: =IF(Reporte1_1!#REF!="","",Reporte1_1!#REF!) -> #REF! | D5: =IF(Reporte1_1!#REF!="","",Reporte1_1!#REF!) -> #REF! | E5: =IF(Reporte1_1!#REF!="","",Reporte1_1!#REF!) -> #REF! | F5: =IF(Reporte1_1!#REF!="","",Reporte1_1!#REF!) -> #REF! | G5: =IF(Reporte1_1!#REF!="","",Reporte1_1!#REF!) -> #REF! | H5: =IF(Reporte1_1!#REF!="","",Reporte1_1!#REF!) -> #REF! | ... Q5: =IF(Reporte1_1!#REF!="","",Reporte1_1!#REF!) -> #REF!
A6: =IF(Reporte1_1!#REF!="","",Reporte1_1!#REF!) -> #REF! | B6: =IF(Reporte1_1!#REF!="","",Reporte1_1!#REF!) -> #REF! | C6: =IF(Reporte1_1!#REF!="","",Reporte1_1!#REF!) -> #REF! | D6: =IF(Reporte1_1!#REF!="","",Reporte1_1!#REF!) -> #REF! | E6: =IF(Reporte1_1!#REF!="","",Reporte1_1!#REF!) -> #REF! | F6: =IF(Reporte1_1!#REF!="","",Reporte1_1!#REF!) -> #REF! | G6: =IF(Reporte1_1!#REF!="","",Reporte1_1!#REF!) -> #REF! | H6: =IF(Reporte1_1!#REF!="","",Reporte1_1!#REF!) -> #REF! | ... Q6: =IF(Reporte1_1!#REF!="","",Reporte1_1!#REF!) -> #REF!
A7: =IF(Reporte1_1!#REF!="","",Reporte1_1!#REF!) -> #REF! | B7: =IF(Reporte1_1!#REF!="","",Reporte1_1!#REF!) -> #REF! | C7: =IF(Reporte1_1!#REF!="","",Reporte1_1!#REF!) -> #REF! | D7: =IF(Reporte1_1!#REF!="","",Reporte1_1!#REF!) -> #REF! | E7: =IF(Reporte1_1!#REF!="","",Reporte1_1!#REF!) -> #REF! | F7: =IF(Reporte1_1!#REF!="","",Reporte1_1!#REF!) -> #REF! | G7: =IF(Reporte1_1!#REF!="","",Reporte1_1!#REF!) -> #REF! | H7: =IF(Reporte1_1!#REF!="","",Reporte1_1!#REF!) -> #REF! | ... Q7: =IF(Reporte1_1!#REF!="","",Reporte1_1!#REF!) -> #REF!
A8: =IF(Reporte1_1!#REF!="","",Reporte1_1!#REF!) -> #REF! | B8: =IF(Reporte1_1!#REF!="","",Reporte1_1!#REF!) -> #REF! | C8: =IF(Reporte1_1!#REF!="","",Reporte1_1!#REF!) -> #REF! | D8: =IF(Reporte1_1!#REF!="","",Reporte1_1!#REF!) -> #REF! | E8: =IF(Reporte1_1!#REF!="","",Reporte1_1!#REF!) -> #REF! | F8: =IF(Reporte1_1!#REF!="","",Reporte1_1!#REF!) -> #REF! | G8: =IF(Reporte1_1!#REF!="","",Reporte1_1!#REF!) -> #REF! | H8: =IF(Reporte1_1!#REF!="","",Reporte1_1!#REF!) -> #REF! | ... Q8: =IF(Reporte1_1!#REF!="","",Reporte1_1!#REF!) -> #REF!
A9: =IF(Reporte1_1!#REF!="","",Reporte1_1!#REF!) -> #REF! | B9: =IF(Reporte1_1!#REF!="","",Reporte1_1!#REF!) -> #REF! | C9: =IF(Reporte1_1!#REF!="","",Reporte1_1!#REF!) -> #REF! | D9: =IF(Reporte1_1!#REF!="","",Reporte1_1!#REF!) -> #REF! | E9: =IF(Reporte1_1!#REF!="","",Reporte1_1!#REF!) -> #REF! | F9: =IF(Reporte1_1!#REF!="","",Reporte1_1!#REF!) -> #REF! | G9: =IF(Reporte1_1!#REF!="","",Reporte1_1!#REF!) -> #REF! | H9: =IF(Reporte1_1!#REF!="","",Reporte1_1!#REF!) -> #REF! | ... Q9: =IF(Reporte1_1!#REF!="","",Reporte1_1!#REF!) -> #REF!
A10: =IF(Reporte1_1!#REF!="","",Reporte1_1!#REF!) -> #REF! | B10: =IF(Reporte1_1!#REF!="","",Reporte1_1!#REF!) -> #REF! | C10: =IF(Reporte1_1!#REF!="","",Reporte1_1!#REF!) -> #REF! | D10: =IF(Reporte1_1!#REF!="","",Reporte1_1!#REF!) -> #REF! | E10: =IF(Reporte1_1!#REF!="","",Reporte1_1!#REF!) -> #REF! | F10: =IF(Reporte1_1!#REF!="","",Reporte1_1!#REF!) -> #REF! | G10: =IF(Reporte1_1!#REF!="","",Reporte1_1!#REF!) -> #REF! | H10: =IF(Reporte1_1!#REF!="","",Reporte1_1!#REF!) -> #REF! | ... Q10: =IF(Reporte1_1!#REF!="","",Reporte1_1!#REF!) -> #REF!
A11: =IF(Reporte1_1!#REF!="","",Reporte1_1!#REF!) -> #REF! | B11: =IF(Reporte1_1!#REF!="","",Reporte1_1!#REF!) -> #REF! | C11: =IF(Reporte1_1!#REF!="","",Reporte1_1!#REF!) -> #REF! | D11: =IF(Reporte1_1!#REF!="","",Reporte1_1!#REF!) -> #REF! | E11: =IF(Reporte1_1!#REF!="","",Reporte1_1!#REF!) -> #REF! | F11: =IF(Reporte1_1!#REF!="","",Reporte1_1!#REF!) -> #REF! | G11: =IF(Reporte1_1!#REF!="","",Reporte1_1!#REF!) -> #REF! | H11: =IF(Reporte1_1!#REF!="","",Reporte1_1!#REF!) -> #REF! | ... Q11: =IF(Reporte1_1!#REF!="","",Reporte1_1!#REF!) -> #REF!
A12: =IF(Reporte1_1!#REF!="","",Reporte1_1!#REF!) -> #REF! | B12: =IF(Reporte1_1!#REF!="","",Reporte1_1!#REF!) -> #REF! | C12: =IF(Reporte1_1!#REF!="","",Reporte1_1!#REF!) -> #REF! | D12: =IF(Reporte1_1!#REF!="","",Reporte1_1!#REF!) -> #REF! | E12: =IF(Reporte1_1!#REF!="","",Reporte1_1!#REF!) -> #REF! | F12: =IF(Reporte1_1!#REF!="","",Reporte1_1!#REF!) -> #REF! | G12: =IF(Reporte1_1!#REF!="","",Reporte1_1!#REF!) -> #REF! | H12: =IF(Reporte1_1!#REF!="","",Reporte1_1!#REF!) -> #REF! | ... Q12: =IF(Reporte1_1!#REF!="","",Reporte1_1!#REF!) -> #REF!
A13: =IF(Reporte1_1!#REF!="","",Reporte1_1!#REF!) -> #REF! | B13: =IF(Reporte1_1!#REF!="","",Reporte1_1!#REF!) -> #REF! | C13: =IF(Reporte1_1!#REF!="","",Reporte1_1!#REF!) -> #REF! | D13: =IF(Reporte1_1!#REF!="","",Reporte1_1!#REF!) -> #REF! | E13: =IF(Reporte1_1!#REF!="","",Reporte1_1!#REF!) -> #REF! | F13: =IF(Reporte1_1!#REF!="","",Reporte1_1!#REF!) -> #REF! | G13: =IF(Reporte1_1!#REF!="","",Reporte1_1!#REF!) -> #REF! | H13: =IF(Reporte1_1!#REF!="","",Reporte1_1!#REF!) -> #REF! | ... Q13: =IF(Reporte1_1!#REF!="","",Reporte1_1!#REF!) -> #REF!
A14: =IF(Reporte1_1!A3="","",Reporte1_1!A3) | B14: =IF(Reporte1_1!C3="","",Reporte1_1!C3) | C14: =IF(Reporte1_1!G3="","",Reporte1_1!G3) | D14: =IF(Reporte1_1!H3="","",Reporte1_1!H3) | E14: =IF(Reporte1_1!I3="","",Reporte1_1!I3) | F14: =IF(Reporte1_1!J3="","",Reporte1_1!J3) | G14: =IF(Reporte1_1!K3="","",Reporte1_1!K3) | H14: =IF(Reporte1_1!L3="","",Reporte1_1!L3) | I14: =IF(Reporte1_1!M3="","",Reporte1_1!M3) | J14: =IF(Reporte1_1!P3="","",Reporte1_1!P3) | K14: =IF(Reporte1_1!Q3="","",Reporte1_1!Q3) | L14: =IF(Reporte1_1!R3="","",Reporte1_1!R3) | M14: =IF(Reporte1_1!S3="","",Reporte1_1!S3) | N14: =IF(Reporte1_1!T3="","",Reporte1_1!T3) | O14: =IF(Reporte1_1!U3="","",Reporte1_1!U3) -> CABEZA | P14: =IF(Reporte1_1!W3="","",Reporte1_1!W3) | Q14: =IF(Reporte1_1!X3="","",Reporte1_1!X3)
A15: =IF(Reporte1_1!A4="","",Reporte1_1!A4) -> SCH-013BT | B15: =IF(Reporte1_1!C4="","",Reporte1_1!C4) -> 45950 | C15: =IF(Reporte1_1!G4="","",Reporte1_1!G4) -> 4 | D15: =IF(Reporte1_1!H4="","",Reporte1_1!H4) -> 385 | E15: =IF(Reporte1_1!I4="","",Reporte1_1!I4) -> 200 | F15: =IF(Reporte1_1!J4="","",Reporte1_1!J4) -> 185 | G15: =IF(Reporte1_1!K4="","",Reporte1_1!K4) -> 59.8 | H15: =IF(Reporte1_1!L4="","",Reporte1_1!L4) -> 48.05 | I15: =IF(Reporte1_1!M4="","",Reporte1_1!M4) -> 299 | J15: =IF(Reporte1_1!P4="","",Reporte1_1!P4) | K15: =IF(Reporte1_1!Q4="","",Reporte1_1!Q4) -> 23.3 | L15: =IF(Reporte1_1!R4="","",Reporte1_1!R4) -> 53.4 | M15: =IF(Reporte1_1!S4="","",Reporte1_1!S4) -> 0 | N15: =IF(Reporte1_1!T4="","",Reporte1_1!T4) -> 0 | O15: =IF(Reporte1_1!U4="","",Reporte1_1!U4) -> 90 | P15: =IF(Reporte1_1!W4="","",Reporte1_1!W4) -> 26 | Q15: =IF(Reporte1_1!X4="","",Reporte1_1!X4) -> 426
A16: =IF(Reporte1_1!#REF!="","",Reporte1_1!#REF!) -> #REF! | B16: =IF(Reporte1_1!#REF!="","",Reporte1_1!#REF!) -> #REF! | C16: =IF(Reporte1_1!#REF!="","",Reporte1_1!#REF!) -> #REF! | D16: =IF(Reporte1_1!#REF!="","",Reporte1_1!#REF!) -> #REF! | E16: =IF(Reporte1_1!#REF!="","",Reporte1_1!#REF!) -> #REF! | F16: =IF(Reporte1_1!#REF!="","",Reporte1_1!#REF!) -> #REF! | G16: =IF(Reporte1_1!#REF!="","",Reporte1_1!#REF!) -> #REF! | H16: =IF(Reporte1_1!#REF!="","",Reporte1_1!#REF!) -> #REF! | ... Q16: =IF(Reporte1_1!#REF!="","",Reporte1_1!#REF!) -> #REF!
A17: =IF(Reporte1_1!#REF!="","",Reporte1_1!#REF!) -> #REF! | B17: =IF(Reporte1_1!#REF!="","",Reporte1_1!#REF!) -> #REF! | C17: =IF(Reporte1_1!#REF!="","",Reporte1_1!#REF!) -> #REF! | D17: =IF(Reporte1_1!#REF!="","",Reporte1_1!#REF!) -> #REF! | E17: =IF(Reporte1_1!#REF!="","",Reporte1_1!#REF!) -> #REF! | F17: =IF(Reporte1_1!#REF!="","",Reporte1_1!#REF!) -> #REF! | G17: =IF(Reporte1_1!#REF!="","",Reporte1_1!#REF!) -> #REF! | H17: =IF(Reporte1_1!#REF!="","",Reporte1_1!#REF!) -> #REF! | ... Q17: =IF(Reporte1_1!#REF!="","",Reporte1_1!#REF!) -> #REF!
A18: =IF(Reporte1_1!A10="","",Reporte1_1!A10) -> SCH-083HI | B18: =IF(Reporte1_1!C10="","",Reporte1_1!C10) -> 45946 | C18: =IF(Reporte1_1!G10="","",Reporte1_1!G10) -> 4 | D18: =IF(Reporte1_1!H10="","",Reporte1_1!H10) -> 1702 | E18: =IF(Reporte1_1!I10="","",Reporte1_1!I10) -> 255 | F18: =IF(Reporte1_1!J10="","",Reporte1_1!J10) -> 1447 | G18: =IF(Reporte1_1!K10="","",Reporte1_1!K10) -> 2.04 | H18: =IF(Reporte1_1!L10="","",Reporte1_1!L10) -> 85.02 | I18: =IF(Reporte1_1!M10="","",Reporte1_1!M10) -> 8 | J18: =IF(Reporte1_1!P10="","",Reporte1_1!P10) | K18: =IF(Reporte1_1!Q10="","",Reporte1_1!Q10) -> 27.7 | L18: =IF(Reporte1_1!R10="","",Reporte1_1!R10) -> 58 | M18: =IF(Reporte1_1!S10="","",Reporte1_1!S10) -> 0 | N18: =IF(Reporte1_1!T10="","",Reporte1_1!T10) -> 0 | O18: =IF(Reporte1_1!U10="","",Reporte1_1!U10) -> 100 | P18: =IF(Reporte1_1!W10="","",Reporte1_1!W10) -> 62 | Q18: =IF(Reporte1_1!X10="","",Reporte1_1!X10) -> 426
A19: =IF(Reporte1_1!#REF!="","",Reporte1_1!#REF!) -> #REF! | B19: =IF(Reporte1_1!#REF!="","",Reporte1_1!#REF!) -> #REF! | C19: =IF(Reporte1_1!#REF!="","",Reporte1_1!#REF!) -> #REF! | D19: =IF(Reporte1_1!#REF!="","",Reporte1_1!#REF!) -> #REF! | E19: =IF(Reporte1_1!#REF!="","",Reporte1_1!#REF!) -> #REF! | F19: =IF(Reporte1_1!#REF!="","",Reporte1_1!#REF!) -> #REF! | G19: =IF(Reporte1_1!#REF!="","",Reporte1_1!#REF!) -> #REF! | H19: =IF(Reporte1_1!#REF!="","",Reporte1_1!#REF!) -> #REF! | ... Q19: =IF(Reporte1_1!#REF!="","",Reporte1_1!#REF!) -> #REF!
A20: =IF(Reporte1_1!A12="","",Reporte1_1!A12) -> SCH-088T | B20: =IF(Reporte1_1!C12="","",Reporte1_1!C12) -> 45940 | C20: =IF(Reporte1_1!G12="","",Reporte1_1!G12) -> 3 | D20: =IF(Reporte1_1!H12="","",Reporte1_1!H12) -> 1189 | E20: =IF(Reporte1_1!I12="","",Reporte1_1!I12) -> 618 | F20: =IF(Reporte1_1!J12="","",Reporte1_1!J12) -> 571 | G20: =IF(Reporte1_1!K12="","",Reporte1_1!K12) -> 234.84 | H20: =IF(Reporte1_1!L12="","",Reporte1_1!L12) -> 48.02 | I20: =IF(Reporte1_1!M12="","",Reporte1_1!M12) -> 380 | J20: =IF(Reporte1_1!P12="","",Reporte1_1!P12) | K20: =IF(Reporte1_1!Q12="","",Reporte1_1!Q12) -> 28.1 | L20: =IF(Reporte1_1!R12="","",Reporte1_1!R12) -> 60.5 | M20: =IF(Reporte1_1!S12="","",Reporte1_1!S12) -> 0 | N20: =IF(Reporte1_1!T12="","",Reporte1_1!T12) -> 0 | O20: =IF(Reporte1_1!U12="","",Reporte1_1!U12) -> 200 | P20: =IF(Reporte1_1!W12="","",Reporte1_1!W12) -> 43 | Q20: =IF(Reporte1_1!X12="","",Reporte1_1!X12) -> 444
A21: =IF(Reporte1_1!A15="","",Reporte1_1!A15) -> SCH-101U | B21: =IF(Reporte1_1!C15="","",Reporte1_1!C15) -> 45952 | C21: =IF(Reporte1_1!G15="","",Reporte1_1!G15) -> 4 | D21: =IF(Reporte1_1!H15="","",Reporte1_1!H15) -> 864 | E21: =IF(Reporte1_1!I15="","",Reporte1_1!I15) -> 274 | F21: =IF(Reporte1_1!J15="","",Reporte1_1!J15) -> 590 | G21: =IF(Reporte1_1!K15="","",Reporte1_1!K15) -> 55.6 | H21: =IF(Reporte1_1!L15="","",Reporte1_1!L15) -> 68.31 | I21: =IF(Reporte1_1!M15="","",Reporte1_1!M15) -> 203 | J21: =IF(Reporte1_1!P15="","",Reporte1_1!P15) | K21: =IF(Reporte1_1!Q15="","",Reporte1_1!Q15) -> 26.5 | L21: =IF(Reporte1_1!R15="","",Reporte1_1!R15) -> 0 | M21: =IF(Reporte1_1!S15="","",Reporte1_1!S15) -> 0 | N21: =IF(Reporte1_1!T15="","",Reporte1_1!T15) -> 2217 | O21: =IF(Reporte1_1!U15="","",Reporte1_1!U15) -> 3750 | P21: =IF(Reporte1_1!W15="","",Reporte1_1!W15) -> 0 | Q21: =IF(Reporte1_1!X15="","",Reporte1_1!X15) -> 0
A22: =IF(Reporte1_1!#REF!="","",Reporte1_1!#REF!) -> #REF! | B22: =IF(Reporte1_1!#REF!="","",Reporte1_1!#REF!) -> #REF! | C22: =IF(Reporte1_1!#REF!="","",Reporte1_1!#REF!) -> #REF! | D22: =IF(Reporte1_1!#REF!="","",Reporte1_1!#REF!) -> #REF! | E22: =IF(Reporte1_1!#REF!="","",Reporte1_1!#REF!) -> #REF! | F22: =IF(Reporte1_1!#REF!="","",Reporte1_1!#REF!) -> #REF! | G22: =IF(Reporte1_1!#REF!="","",Reporte1_1!#REF!) -> #REF! | H22: =IF(Reporte1_1!#REF!="","",Reporte1_1!#REF!) -> #REF! | ... Q22: =IF(Reporte1_1!#REF!="","",Reporte1_1!#REF!) -> #REF!
A23: =IF(Reporte1_1!#REF!="","",Reporte1_1!#REF!) -> #REF! | B23: =IF(Reporte1_1!#REF!="","",Reporte1_1!#REF!) -> #REF! | C23: =IF(Reporte1_1!#REF!="","",Reporte1_1!#REF!) -> #REF! | D23: =IF(Reporte1_1!#REF!="","",Reporte1_1!#REF!) -> #REF! | E23: =IF(Reporte1_1!#REF!="","",Reporte1_1!#REF!) -> #REF! | F23: =IF(Reporte1_1!#REF!="","",Reporte1_1!#REF!) -> #REF! | G23: =IF(Reporte1_1!#REF!="","",Reporte1_1!#REF!) -> #REF! | H23: =IF(Reporte1_1!#REF!="","",Reporte1_1!#REF!) -> #REF! | ... Q23: =IF(Reporte1_1!#REF!="","",Reporte1_1!#REF!) -> #REF!
A24: =IF(Reporte1_1!#REF!="","",Reporte1_1!#REF!) -> #REF! | B24: =IF(Reporte1_1!#REF!="","",Reporte1_1!#REF!) -> #REF! | C24: =IF(Reporte1_1!#REF!="","",Reporte1_1!#REF!) -> #REF! | D24: =IF(Reporte1_1!#REF!="","",Reporte1_1!#REF!) -> #REF! | E24: =IF(Reporte1_1!#REF!="","",Reporte1_1!#REF!) -> #REF! | F24: =IF(Reporte1_1!#REF!="","",Reporte1_1!#REF!) -> #REF! | G24: =IF(Reporte1_1!#REF!="","",Reporte1_1!#REF!) -> #REF! | H24: =IF(Reporte1_1!#REF!="","",Reporte1_1!#REF!) -> #REF! | ... Q24: =IF(Reporte1_1!#REF!="","",Reporte1_1!#REF!) -> #REF!
A25: =IF(Reporte1_1!#REF!="","",Reporte1_1!#REF!) -> #REF! | B25: =IF(Reporte1_1!#REF!="","",Reporte1_1!#REF!) -> #REF! | C25: =IF(Reporte1_1!#REF!="","",Reporte1_1!#REF!) -> #REF! | D25: =IF(Reporte1_1!#REF!="","",Reporte1_1!#REF!) -> #REF! | E25: =IF(Reporte1_1!#REF!="","",Reporte1_1!#REF!) -> #REF! | F25: =IF(Reporte1_1!#REF!="","",Reporte1_1!#REF!) -> #REF! | G25: =IF(Reporte1_1!#REF!="","",Reporte1_1!#REF!) -> #REF! | H25: =IF(Reporte1_1!#REF!="","",Reporte1_1!#REF!) -> #REF! | ... Q25: =IF(Reporte1_1!#REF!="","",Reporte1_1!#REF!) -> #REF!
A27: =IF(Reporte1_1!#REF!="","",Reporte1_1!#REF!) -> #REF! | B27: =IF(Reporte1_1!#REF!="","",Reporte1_1!#REF!) -> #REF! | C27: =IF(Reporte1_1!#REF!="","",Reporte1_1!#REF!) -> #REF! | D27: =IF(Reporte1_1!#REF!="","",Reporte1_1!#REF!) -> #REF! | E27: =IF(Reporte1_1!#REF!="","",Reporte1_1!#REF!) -> #REF! | F27: =IF(Reporte1_1!#REF!="","",Reporte1_1!#REF!) -> #REF! | G27: =IF(Reporte1_1!#REF!="","",Reporte1_1!#REF!) -> #REF! | H27: =IF(Reporte1_1!#REF!="","",Reporte1_1!#REF!) -> #REF! | ... Q27: =IF(Reporte1_1!#REF!="","",Reporte1_1!#REF!) -> #REF!
A28: =IF(Reporte1_1!#REF!="","",Reporte1_1!#REF!) -> #REF! | B28: =IF(Reporte1_1!#REF!="","",Reporte1_1!#REF!) -> #REF! | C28: =IF(Reporte1_1!#REF!="","",Reporte1_1!#REF!) -> #REF! | D28: =IF(Reporte1_1!#REF!="","",Reporte1_1!#REF!) -> #REF! | E28: =IF(Reporte1_1!#REF!="","",Reporte1_1!#REF!) -> #REF! | F28: =IF(Reporte1_1!#REF!="","",Reporte1_1!#REF!) -> #REF! | G28: =IF(Reporte1_1!#REF!="","",Reporte1_1!#REF!) -> #REF! | H28: =IF(Reporte1_1!#REF!="","",Reporte1_1!#REF!) -> #REF! | ... Q28: =IF(Reporte1_1!#REF!="","",Reporte1_1!#REF!) -> #REF!
A29: =IF(Reporte1_1!#REF!="","",Reporte1_1!#REF!) -> #REF! | B29: =IF(Reporte1_1!#REF!="","",Reporte1_1!#REF!) -> #REF! | C29: =IF(Reporte1_1!#REF!="","",Reporte1_1!#REF!) -> #REF! | D29: =IF(Reporte1_1!#REF!="","",Reporte1_1!#REF!) -> #REF! | E29: =IF(Reporte1_1!#REF!="","",Reporte1_1!#REF!) -> #REF! | F29: =IF(Reporte1_1!#REF!="","",Reporte1_1!#REF!) -> #REF! | G29: =IF(Reporte1_1!#REF!="","",Reporte1_1!#REF!) -> #REF! | H29: =IF(Reporte1_1!#REF!="","",Reporte1_1!#REF!) -> #REF! | ... Q29: =IF(Reporte1_1!#REF!="","",Reporte1_1!#REF!) -> #REF!
A30: =IF(Reporte1_1!#REF!="","",Reporte1_1!#REF!) -> #REF! | B30: =IF(Reporte1_1!#REF!="","",Reporte1_1!#REF!) -> #REF! | C30: =IF(Reporte1_1!#REF!="","",Reporte1_1!#REF!) -> #REF! | D30: =IF(Reporte1_1!#REF!="","",Reporte1_1!#REF!) -> #REF! | E30: =IF(Reporte1_1!#REF!="","",Reporte1_1!#REF!) -> #REF! | F30: =IF(Reporte1_1!#REF!="","",Reporte1_1!#REF!) -> #REF! | G30: =IF(Reporte1_1!#REF!="","",Reporte1_1!#REF!) -> #REF! | H30: =IF(Reporte1_1!#REF!="","",Reporte1_1!#REF!) -> #REF! | ... Q30: =IF(Reporte1_1!#REF!="","",Reporte1_1!#REF!) -> #REF!
A31: =IF(Reporte1_1!#REF!="","",Reporte1_1!#REF!) -> #REF! | B31: =IF(Reporte1_1!#REF!="","",Reporte1_1!#REF!) -> #REF! | C31: =IF(Reporte1_1!#REF!="","",Reporte1_1!#REF!) -> #REF! | D31: =IF(Reporte1_1!#REF!="","",Reporte1_1!#REF!) -> #REF! | E31: =IF(Reporte1_1!#REF!="","",Reporte1_1!#REF!) -> #REF! | F31: =IF(Reporte1_1!#REF!="","",Reporte1_1!#REF!) -> #REF! | G31: =IF(Reporte1_1!#REF!="","",Reporte1_1!#REF!) -> #REF! | H31: =IF(Reporte1_1!#REF!="","",Reporte1_1!#REF!) -> #REF! | ... Q31: =IF(Reporte1_1!#REF!="","",Reporte1_1!#REF!) -> #REF!
A32: =IF(Reporte1_1!#REF!="","",Reporte1_1!#REF!) -> #REF! | B32: =IF(Reporte1_1!#REF!="","",Reporte1_1!#REF!) -> #REF! | C32: =IF(Reporte1_1!#REF!="","",Reporte1_1!#REF!) -> #REF! | D32: =IF(Reporte1_1!#REF!="","",Reporte1_1!#REF!) -> #REF! | E32: =IF(Reporte1_1!#REF!="","",Reporte1_1!#REF!) -> #REF! | F32: =IF(Reporte1_1!#REF!="","",Reporte1_1!#REF!) -> #REF! | G32: =IF(Reporte1_1!#REF!="","",Reporte1_1!#REF!) -> #REF! | H32: =IF(Reporte1_1!#REF!="","",Reporte1_1!#REF!) -> #REF! | ... Q32: =IF(Reporte1_1!#REF!="","",Reporte1_1!#REF!) -> #REF!
A33: =IF(Reporte1_1!A36="","",Reporte1_1!A36) -> SCHAP-269UI | B33: =IF(Reporte1_1!C36="","",Reporte1_1!C36) -> 45952 | C33: =IF(Reporte1_1!G36="","",Reporte1_1!G36) -> 3 | D33: =IF(Reporte1_1!H36="","",Reporte1_1!H36) -> 321 | E33: =IF(Reporte1_1!I36="","",Reporte1_1!I36) -> 318 | F33: =IF(Reporte1_1!J36="","",Reporte1_1!J36) -> 3 | G33: =IF(Reporte1_1!K36="","",Reporte1_1!K36) -> 49.29 | H33: =IF(Reporte1_1!L36="","",Reporte1_1!L36) -> 0.94 | I33: =IF(Reporte1_1!M36="","",Reporte1_1!M36) -> 155 | J33: =IF(Reporte1_1!P36="","",Reporte1_1!P36) | K33: =IF(Reporte1_1!Q36="","",Reporte1_1!Q36) -> 19.4 | L33: =IF(Reporte1_1!R36="","",Reporte1_1!R36) -> 52 | M33: =IF(Reporte1_1!S36="","",Reporte1_1!S36) -> 0 | N33: =IF(Reporte1_1!T36="","",Reporte1_1!T36) -> 0 | O33: =IF(Reporte1_1!U36="","",Reporte1_1!U36) -> 120 | P33: =IF(Reporte1_1!W36="","",Reporte1_1!W36) -> 49 | Q33: =IF(Reporte1_1!X36="","",Reporte1_1!X36) -> 417
A34: =IF(Reporte1_1!#REF!="","",Reporte1_1!#REF!) -> #REF! | B34: =IF(Reporte1_1!#REF!="","",Reporte1_1!#REF!) -> #REF! | C34: =IF(Reporte1_1!#REF!="","",Reporte1_1!#REF!) -> #REF! | D34: =IF(Reporte1_1!#REF!="","",Reporte1_1!#REF!) -> #REF! | E34: =IF(Reporte1_1!#REF!="","",Reporte1_1!#REF!) -> #REF! | F34: =IF(Reporte1_1!#REF!="","",Reporte1_1!#REF!) -> #REF! | G34: =IF(Reporte1_1!#REF!="","",Reporte1_1!#REF!) -> #REF! | H34: =IF(Reporte1_1!#REF!="","",Reporte1_1!#REF!) -> #REF! | ... Q34: =IF(Reporte1_1!#REF!="","",Reporte1_1!#REF!) -> #REF!
A35: =IF(Reporte1_1!#REF!="","",Reporte1_1!#REF!) -> #REF! | B35: =IF(Reporte1_1!#REF!="","",Reporte1_1!#REF!) -> #REF! | C35: =IF(Reporte1_1!#REF!="","",Reporte1_1!#REF!) -> #REF! | D35: =IF(Reporte1_1!#REF!="","",Reporte1_1!#REF!) -> #REF! | E35: =IF(Reporte1_1!#REF!="","",Reporte1_1!#REF!) -> #REF! | F35: =IF(Reporte1_1!#REF!="","",Reporte1_1!#REF!) -> #REF! | G35: =IF(Reporte1_1!#REF!="","",Reporte1_1!#REF!) -> #REF! | H35: =IF(Reporte1_1!#REF!="","",Reporte1_1!#REF!) -> #REF! | ... Q35: =IF(Reporte1_1!#REF!="","",Reporte1_1!#REF!) -> #REF!
A36: =IF(Reporte1_1!#REF!="","",Reporte1_1!#REF!) -> #REF! | B36: =IF(Reporte1_1!#REF!="","",Reporte1_1!#REF!) -> #REF! | C36: =IF(Reporte1_1!#REF!="","",Reporte1_1!#REF!) -> #REF! | D36: =IF(Reporte1_1!#REF!="","",Reporte1_1!#REF!) -> #REF! | E36: =IF(Reporte1_1!#REF!="","",Reporte1_1!#REF!) -> #REF! | F36: =IF(Reporte1_1!#REF!="","",Reporte1_1!#REF!) -> #REF! | G36: =IF(Reporte1_1!#REF!="","",Reporte1_1!#REF!) -> #REF! | H36: =IF(Reporte1_1!#REF!="","",Reporte1_1!#REF!) -> #REF! | ... Q36: =IF(Reporte1_1!#REF!="","",Reporte1_1!#REF!) -> #REF!
A37: =IF(Reporte1_1!#REF!="","",Reporte1_1!#REF!) -> #REF! | B37: =IF(Reporte1_1!#REF!="","",Reporte1_1!#REF!) -> #REF! | C37: =IF(Reporte1_1!#REF!="","",Reporte1_1!#REF!) -> #REF! | D37: =IF(Reporte1_1!#REF!="","",Reporte1_1!#REF!) -> #REF! | E37: =IF(Reporte1_1!#REF!="","",Reporte1_1!#REF!) -> #REF! | F37: =IF(Reporte1_1!#REF!="","",Reporte1_1!#REF!) -> #REF! | G37: =IF(Reporte1_1!#REF!="","",Reporte1_1!#REF!) -> #REF! | H37: =IF(Reporte1_1!#REF!="","",Reporte1_1!#REF!) -> #REF! | ... Q37: =IF(Reporte1_1!#REF!="","",Reporte1_1!#REF!) -> #REF!
A38: =IF(Reporte1_1!#REF!="","",Reporte1_1!#REF!) -> #REF! | B38: =IF(Reporte1_1!#REF!="","",Reporte1_1!#REF!) -> #REF! | C38: =IF(Reporte1_1!#REF!="","",Reporte1_1!#REF!) -> #REF! | D38: =IF(Reporte1_1!#REF!="","",Reporte1_1!#REF!) -> #REF! | E38: =IF(Reporte1_1!#REF!="","",Reporte1_1!#REF!) -> #REF! | F38: =IF(Reporte1_1!#REF!="","",Reporte1_1!#REF!) -> #REF! | G38: =IF(Reporte1_1!#REF!="","",Reporte1_1!#REF!) -> #REF! | H38: =IF(Reporte1_1!#REF!="","",Reporte1_1!#REF!) -> #REF! | ... Q38: =IF(Reporte1_1!#REF!="","",Reporte1_1!#REF!) -> #REF!
A39: =IF(Reporte1_1!#REF!="","",Reporte1_1!#REF!) -> #REF! | B39: =IF(Reporte1_1!#REF!="","",Reporte1_1!#REF!) -> #REF! | C39: =IF(Reporte1_1!#REF!="","",Reporte1_1!#REF!) -> #REF! | D39: =IF(Reporte1_1!#REF!="","",Reporte1_1!#REF!) -> #REF! | E39: =IF(Reporte1_1!#REF!="","",Reporte1_1!#REF!) -> #REF! | F39: =IF(Reporte1_1!#REF!="","",Reporte1_1!#REF!) -> #REF! | G39: =IF(Reporte1_1!#REF!="","",Reporte1_1!#REF!) -> #REF! | H39: =IF(Reporte1_1!#REF!="","",Reporte1_1!#REF!) -> #REF! | ... Q39: =IF(Reporte1_1!#REF!="","",Reporte1_1!#REF!) -> #REF!
A40: =IF(Reporte1_1!#REF!="","",Reporte1_1!#REF!) -> #REF! | B40: =IF(Reporte1_1!#REF!="","",Reporte1_1!#REF!) -> #REF! | C40: =IF(Reporte1_1!#REF!="","",Reporte1_1!#REF!) -> #REF! | D40: =IF(Reporte1_1!#REF!="","",Reporte1_1!#REF!) -> #REF! | E40: =IF(Reporte1_1!#REF!="","",Reporte1_1!#REF!) -> #REF! | F40: =IF(Reporte1_1!#REF!="","",Reporte1_1!#REF!) -> #REF! | G40: =IF(Reporte1_1!#REF!="","",Reporte1_1!#REF!) -> #REF! | H40: =IF(Reporte1_1!#REF!="","",Reporte1_1!#REF!) -> #REF! | ... Q40: =IF(Reporte1_1!#REF!="","",Reporte1_1!#REF!) -> #REF!
A41: =IF(Reporte1_1!#REF!="","",Reporte1_1!#REF!) -> #REF! | B41: =IF(Reporte1_1!#REF!="","",Reporte1_1!#REF!) -> #REF! | C41: =IF(Reporte1_1!#REF!="","",Reporte1_1!#REF!) -> #REF! | D41: =IF(Reporte1_1!#REF!="","",Reporte1_1!#REF!) -> #REF! | E41: =IF(Reporte1_1!#REF!="","",Reporte1_1!#REF!) -> #REF! | F41: =IF(Reporte1_1!#REF!="","",Reporte1_1!#REF!) -> #REF! | G41: =IF(Reporte1_1!#REF!="","",Reporte1_1!#REF!) -> #REF! | H41: =IF(Reporte1_1!#REF!="","",Reporte1_1!#REF!) -> #REF! | ... Q41: =IF(Reporte1_1!#REF!="","",Reporte1_1!#REF!) -> #REF!
A42: =IF(Reporte1_1!#REF!="","",Reporte1_1!#REF!) -> #REF! | B42: =IF(Reporte1_1!#REF!="","",Reporte1_1!#REF!) -> #REF! | C42: =IF(Reporte1_1!#REF!="","",Reporte1_1!#REF!) -> #REF! | D42: =IF(Reporte1_1!#REF!="","",Reporte1_1!#REF!) -> #REF! | E42: =IF(Reporte1_1!#REF!="","",Reporte1_1!#REF!) -> #REF! | F42: =IF(Reporte1_1!#REF!="","",Reporte1_1!#REF!) -> #REF! | G42: =IF(Reporte1_1!#REF!="","",Reporte1_1!#REF!) -> #REF! | H42: =IF(Reporte1_1!#REF!="","",Reporte1_1!#REF!) -> #REF! | ... Q42: =IF(Reporte1_1!#REF!="","",Reporte1_1!#REF!) -> #REF!
...

Sheet IMPRIMIR
A1: FECHA: | B1: =TODAY() -> 46016
A3: =IF(Reporte1_1!A1="","",Reporte1_1!A1) -> SACHA CENTRAL
A4: =IF(Reporte1_1!A2="","",Reporte1_1!A2) -> POZO | B4: =IF(Reporte1_1!C2="","",Reporte1_1!C2) -> FECHA | C4: =IF(Reporte1_1!D2="","",Reporte1_1!D2) -> CAMPO | D4: =IF(Reporte1_1!G2="","",Reporte1_1!G2) -> HORAS | E4: =IF(Reporte1_1!H2="","",Reporte1_1!H2) -> BFPD | F4: =IF(Reporte1_1!I2="","",Reporte1_1!I2) -> BPPD | G4: =IF(Reporte1_1!J2="","",Reporte1_1!J2) -> BAPD | H4: =IF(Reporte1_1!K2="","",Reporte1_1!K2) -> MSCF | I4: =IF(Reporte1_1!L2="","",Reporte1_1!L2) -> BSW | J4: =IF(Reporte1_1!M2="","",Reporte1_1!M2) -> GOR | K4: =IF(Reporte1_1!V2="","",Reporte1_1!V2) -> PIP | L4: =IF(Reporte1_1!Q2="","",Reporte1_1!Q2) -> API | M4: =IF(Reporte1_1!R2="","",Reporte1_1!R2) -> FREC | N4: =IF(Reporte1_1!S2="","",Reporte1_1!S2) -> P. INY | O4: =IF(Reporte1_1!T2="","",Reporte1_1!T2) -> B. INY | P4: =IF(Reporte1_1!U2="","",Reporte1_1!U2) -> PSI | Q4: =IF(Reporte1_1!N2="","",Reporte1_1!N2) -> T. | R4: =IF(Reporte1_1!Y2="","",Reporte1_1!Y2) -> SALIN. | S4: =IF(Reporte1_1!AA2="","",Reporte1_1!AA2) -> BPPD
A5: POZO | B5: FECHA | C5: CAMPO | D5: HORAS | E5: BFPD | F5: BPPD | G5: BAPD | H5: MSCF | I5: BSW | J5: GOR | K5: PIP | L5: API | M5: FREC | N5: P. INY | O5: B. INY | P5: PSI | Q5: T. | R5: SALIN. | S5: BPPD
A6: POZO | B6: FECHA | C6: CAMPO | D6: HORAS | E6: BFPD | F6: BPPD | G6: BAPD | H6: MSCF | I6: BSW | J6: GOR | K6: PIP | L6: API | M6: FREC | N6: P. INY | O6: B. INY | P6: PSI | Q6: T. | R6: SALIN. | S6: BPPD
A7: POZO | B7: FECHA | C7: PEC | D7: HORAS | E7: BFPD | F7: BPPD | G7: BAPD | H7: MSCF | I7: BSW | J7: GOR | K7: PIP | L7: API | M7: FREC | N7: P. INY | O7: B. INY | P7: PSI | Q7: T. | R7: VOL | S7: BPPD
A8: =IF(Reporte1_1!A273="","",Reporte1_1!A273) -> TOTAL | B8: =IF(Reporte1_1!C273="","",Reporte1_1!C273) | C8: PEC | D8: =IF(Reporte1_1!G273="","",Reporte1_1!G273) | E8: =IF(Reporte1_1!H273="","",Reporte1_1!H273) -> 72902.3 | F8: =IF(Reporte1_1!I273="","",Reporte1_1!I273) -> 34657.3 | G8: =IF(Reporte1_1!J273="","",Reporte1_1!J273) -> 38245 | H8: =IF(Reporte1_1!K273="","",Reporte1_1!K273) -> 13476.5 | I8: =IF(Reporte1_1!L273="","",Reporte1_1!L273) | J8: =IF(Reporte1_1!M273="","",Reporte1_1!M273) -> 389 | K8: =IF(Reporte1_1!V273="","",Reporte1_1!V273) | L8: =IF(Reporte1_1!Q273="","",Reporte1_1!Q273) | M8: =IF(Reporte1_1!R273="","",Reporte1_1!R273) | N8: =IF(Reporte1_1!S273="","",Reporte1_1!S273) | O8: =IF(Reporte1_1!T273="","",Reporte1_1!T273) | P8: =IF(Reporte1_1!U273="","",Reporte1_1!U273) | Q8: =IF(Reporte1_1!N273="","",Reporte1_1!N273) | R8: =IF(Reporte1_1!X273="","",Reporte1_1!X273) | S8: =IF(Reporte1_1!AA273="","",Reporte1_1!AA273) -> 35088.546
A9: =IF(Reporte1_1!A87="","",Reporte1_1!A87) -> TOTAL | B9: =IF(Reporte1_1!C87="","",Reporte1_1!C87) | C9: PEC | D9: =IF(Reporte1_1!G87="","",Reporte1_1!G87) | E9: =IF(Reporte1_1!H87="","",Reporte1_1!H87) -> 32492 | F9: =IF(Reporte1_1!I87="","",Reporte1_1!I87) -> 11326 | G9: =IF(Reporte1_1!J87="","",Reporte1_1!J87) -> 21166 | H9: =IF(Reporte1_1!K87="","",Reporte1_1!K87) -> 2812.1 | I9: =IF(Reporte1_1!L87="","",Reporte1_1!L87) | J9: =IF(Reporte1_1!M87="","",Reporte1_1!M87) -> 248 | K9: =IF(Reporte1_1!V87="","",Reporte1_1!V87) | L9: =IF(Reporte1_1!Q87="","",Reporte1_1!Q87) | M9: =IF(Reporte1_1!R87="","",Reporte1_1!R87) | N9: =IF(Reporte1_1!S87="","",Reporte1_1!S87) | O9: =IF(Reporte1_1!T87="","",Reporte1_1!T87) | P9: =IF(Reporte1_1!U87="","",Reporte1_1!U87) | Q9: =IF(Reporte1_1!N87="","",Reporte1_1!N87) | R9: =IF(Reporte1_1!X87="","",Reporte1_1!X87) | S9: =IF(Reporte1_1!AA87="","",Reporte1_1!AA87) -> 11466.931
A10: =IF(Reporte1_1!A69="","",Reporte1_1!A69) -> SCHAO-473HS1UI | B10: =IF(Reporte1_1!C69="","",Reporte1_1!C69) -> 45942 | C10: PEC | D10: =IF(Reporte1_1!G69="","",Reporte1_1!G69) -> 3 | E10: =IF(Reporte1_1!H69="","",Reporte1_1!H69) -> 4385 | F10: =IF(Reporte1_1!I69="","",Reporte1_1!I69) -> 614 | G10: =IF(Reporte1_1!J69="","",Reporte1_1!J69) -> 3771 | H10: =IF(Reporte1_1!K69="","",Reporte1_1!K69) -> 245.6 | I10: =IF(Reporte1_1!L69="","",Reporte1_1!L69) -> 86 | J10: =IF(Reporte1_1!M69="","",Reporte1_1!M69) -> 400 | K10: =IF(Reporte1_1!V69="","",Reporte1_1!V69) -> 461 | L10: =IF(Reporte1_1!Q69="","",Reporte1_1!Q69) -> 17.9 | M10: =IF(Reporte1_1!R69="","",Reporte1_1!R69) -> 60 | N10: =IF(Reporte1_1!S69="","",Reporte1_1!S69) -> 0 | O10: =IF(Reporte1_1!T69="","",Reporte1_1!T69) -> 0 | P10: =IF(Reporte1_1!U69="","",Reporte1_1!U69) -> 180 | Q10: =IF(Reporte1_1!N69="","",Reporte1_1!N69) -> S4000N|S4000N | R10: =IF(Reporte1_1!X69="","",Reporte1_1!X69) -> 448 | S10: =IF(Reporte1_1!AA69="","",Reporte1_1!AA69) -> 621.64
A11: =IF(Reporte1_1!A161="","",Reporte1_1!A161) -> SCH-128HS | B11: =IF(Reporte1_1!C161="","",Reporte1_1!C161) -> 45950 | C11: PEC | D11: =IF(Reporte1_1!G161="","",Reporte1_1!G161) -> 5 | E11: =IF(Reporte1_1!H161="","",Reporte1_1!H161) -> 3753 | F11: =IF(Reporte1_1!I161="","",Reporte1_1!I161) -> 225 | G11: =IF(Reporte1_1!J161="","",Reporte1_1!J161) -> 3528 | H11: =IF(Reporte1_1!K161="","",Reporte1_1!K161) -> 33.98 | I11: =IF(Reporte1_1!L161="","",Reporte1_1!L161) -> 94.01 | J11: =IF(Reporte1_1!M161="","",Reporte1_1!M161) -> 151 | K11: =IF(Reporte1_1!V161="","",Reporte1_1!V161) -> 2644 | L11: =IF(Reporte1_1!Q161="","",Reporte1_1!Q161) -> 29.8 | M11: =IF(Reporte1_1!R161="","",Reporte1_1!R161) -> 43 | N11: =IF(Reporte1_1!S161="","",Reporte1_1!S161) -> 0 | O11: =IF(Reporte1_1!T161="","",Reporte1_1!T161) -> 0 | P11: =IF(Reporte1_1!U161="","",Reporte1_1!U161) -> 270 | Q11: =IF(Reporte1_1!N161="","",Reporte1_1!N161) -> RC4000 CR-CT|RC4000 CR-CT|RC4000 CR-CT | R11: =IF(Reporte1_1!X161="","",Reporte1_1!X161) -> 319 | S11: =IF(Reporte1_1!AA161="","",Reporte1_1!AA161) -> 227.8
A12: =IF(Reporte1_1!A25="","",Reporte1_1!A25) -> SCHA-409HI | B12: =IF(Reporte1_1!C25="","",Reporte1_1!C25) -> 45940 | C12: PEC | D12: =IF(Reporte1_1!G25="","",Reporte1_1!G25) -> 3 | E12: =IF(Reporte1_1!H25="","",Reporte1_1!H25) -> 3615 | F12: =IF(Reporte1_1!I25="","",Reporte1_1!I25) -> 434 | G12: =IF(Reporte1_1!J25="","",Reporte1_1!J25) -> 3181 | H12: =IF(Reporte1_1!K25="","",Reporte1_1!K25) -> 3.47 | I12: =IF(Reporte1_1!L25="","",Reporte1_1!L25) -> 87.99 | J12: =IF(Reporte1_1!M25="","",Reporte1_1!M25) -> 8 | K12: =IF(Reporte1_1!V25="","",Reporte1_1!V25) -> 2261 | L12: =IF(Reporte1_1!Q25="","",Reporte1_1!Q25) -> 26.9 | M12: =IF(Reporte1_1!R25="","",Reporte1_1!R25) -> 56 | N12: =IF(Reporte1_1!S25="","",Reporte1_1!S25) -> 0 | O12: =IF(Reporte1_1!T25="","",Reporte1_1!T25) -> 0 | P12: =IF(Reporte1_1!U25="","",Reporte1_1!U25) -> 80 | Q12: =IF(Reporte1_1!N25="","",Reporte1_1!N25) -> WD-3000|WD-3000|WD-3000|WD-3000 | R12: =IF(Reporte1_1!X25="","",Reporte1_1!X25) -> 414 | S12: =IF(Reporte1_1!AA25="","",Reporte1_1!AA25) -> 439.4
A13: =IF(Reporte1_1!A72="","",Reporte1_1!A72) -> SCHAO-477HUI | B13: =IF(Reporte1_1!C72="","",Reporte1_1!C72) -> 45947 | C13: PEC | D13: =IF(Reporte1_1!G72="","",Reporte1_1!G72) -> 1 | E13: =IF(Reporte1_1!H72="","",Reporte1_1!H72) -> 3547 | F13: =IF(Reporte1_1!I72="","",Reporte1_1!I72) -> 355 | G13: =IF(Reporte1_1!J72="","",Reporte1_1!J72) -> 3192 | H13: =IF(Reporte1_1!K72="","",Reporte1_1!K72) -> 284 | I13: =IF(Reporte1_1!L72="","",Reporte1_1!L72) -> 89.99 | J13: =IF(Reporte1_1!M72="","",Reporte1_1!M72) -> 800 | K13: =IF(Reporte1_1!V72="","",Reporte1_1!V72) -> 868 | L13: =IF(Reporte1_1!Q72="","",Reporte1_1!Q72) -> 17.4 | M13: =IF(Reporte1_1!R72="","",Reporte1_1!R72) -> 57 | N13: =IF(Reporte1_1!S72="","",Reporte1_1!S72) -> 0 | O13: =IF(Reporte1_1!T72="","",Reporte1_1!T72) -> 0 | P13: =IF(Reporte1_1!U72="","",Reporte1_1!U72) -> 120 | Q13: =IF(Reporte1_1!N72="","",Reporte1_1!N72) -> S4000N|S4000N | R13: =IF(Reporte1_1!X72="","",Reporte1_1!X72) -> 424 | S13: =IF(Reporte1_1!AA72="","",Reporte1_1!AA72) -> 359.418
A14: =IF(Reporte1_1!A58="","",Reporte1_1!A58) -> SCH-106HS | B14: =IF(Reporte1_1!C58="","",Reporte1_1!C58) -> 45952 | C14: PEC | D14: =IF(Reporte1_1!G58="","",Reporte1_1!G58) -> 5 | E14: =IF(Reporte1_1!H58="","",Reporte1_1!H58) -> 3067 | F14: =IF(Reporte1_1!I58="","",Reporte1_1!I58) -> 701 | G14: =IF(Reporte1_1!J58="","",Reporte1_1!J58) -> 2366 | H14: =IF(Reporte1_1!K58="","",Reporte1_1!K58) -> 106.8 | I14: =IF(Reporte1_1!L58="","",Reporte1_1!L58) -> 77.14 | J14: =IF(Reporte1_1!M58="","",Reporte1_1!M58) -> 152 | K14: =IF(Reporte1_1!V58="","",Reporte1_1!V58) -> 550 | L14: =IF(Reporte1_1!Q58="","",Reporte1_1!Q58) -> 26.8 | M14: =IF(Reporte1_1!R58="","",Reporte1_1!R58) -> 59.2 | N14: =IF(Reporte1_1!S58="","",Reporte1_1!S58) -> 0 | O14: =IF(Reporte1_1!T58="","",Reporte1_1!T58) -> 0 | P14: =IF(Reporte1_1!U58="","",Reporte1_1!U58) -> 180 | Q14: =IF(Reporte1_1!N58="","",Reporte1_1!N58) -> D3550N|D3550N|D3500N|D3550N|D20 | R14: =IF(Reporte1_1!X58="","",Reporte1_1!X58) -> 452 | S14: =IF(Reporte1_1!AA58="","",Reporte1_1!AA58) -> 709.723
A15: =IF(Reporte1_1!A143="","",Reporte1_1!A143) -> SCHV-226HS | B15: =IF(Reporte1_1!C143="","",Reporte1_1!C143) -> 45951 | C15: PEC | D15: =IF(Reporte1_1!G143="","",Reporte1_1!G143) -> 3 | E15: =IF(Reporte1_1!H143="","",Reporte1_1!H143) -> 2632 | F15: =IF(Reporte1_1!I143="","",Reporte1_1!I143) -> 237 | G15: =IF(Reporte1_1!J143="","",Reporte1_1!J143) -> 2395 | H15: =IF(Reporte1_1!K143="","",Reporte1_1!K143) -> 5.69 | I15: =IF(Reporte1_1!L143="","",Reporte1_1!L143) -> 91 | J15: =IF(Reporte1_1!M143="","",Reporte1_1!M143) -> 24 | K15: =IF(Reporte1_1!V143="","",Reporte1_1!V143) -> 3009 | L15: =IF(Reporte1_1!Q143="","",Reporte1_1!Q143) -> 24 | M15: =IF(Reporte1_1!R143="","",Reporte1_1!R143) -> 98 | N15: =IF(Reporte1_1!S143="","",Reporte1_1!S143) -> 0 | O15: =IF(Reporte1_1!T143="","",Reporte1_1!T143) -> 0 | P15: =IF(Reporte1_1!U143="","",Reporte1_1!U143) -> 40 | Q15: =IF(Reporte1_1!N143="","",Reporte1_1!N143) -> NH(2500-3100)H|NH(2500-3100)H|NH(2500-3100)H|NH(2500-3100)H | R15: =IF(Reporte1_1!X143="","",Reporte1_1!X143) -> 328 | S15: =IF(Reporte1_1!AA143="","",Reporte1_1!AA143) -> 224.944
A16: =IF(Reporte1_1!A160="","",Reporte1_1!A160) -> SCH-124UI | B16: =IF(Reporte1_1!C160="","",Reporte1_1!C160) -> 45946 | C16: PEC | D16: =IF(Reporte1_1!G160="","",Reporte1_1!G160) -> 5 | E16: =IF(Reporte1_1!H160="","",Reporte1_1!H160) -> 2459 | F16: =IF(Reporte1_1!I160="","",Reporte1_1!I160) -> 295 | G16: =IF(Reporte1_1!J160="","",Reporte1_1!J160) -> 2164 | H16: =IF(Reporte1_1!K160="","",Reporte1_1!K160) -> 59.89 | I16: =IF(Reporte1_1!L160="","",Reporte1_1!L160) -> 88 | J16: =IF(Reporte1_1!M160="","",Reporte1_1!M160) -> 203 | K16: =IF(Reporte1_1!V160="","",Reporte1_1!V160) -> 665 | L16: =IF(Reporte1_1!Q160="","",Reporte1_1!Q160) -> 24.2 | M16: =IF(Reporte1_1!R160="","",Reporte1_1!R160) -> 64 | N16: =IF(Reporte1_1!S160="","",Reporte1_1!S160) -> 0 | O16: =IF(Reporte1_1!T160="","",Reporte1_1!T160) -> 0 | P16: =IF(Reporte1_1!U160="","",Reporte1_1!U160) -> 210 | Q16: =IF(Reporte1_1!N160="","",Reporte1_1!N160) -> E3000 SSD|E3000 SSD|E3000 SSD|E3000 SSD | R16: =IF(Reporte1_1!X160="","",Reporte1_1!X160) -> 454 | S16: =IF(Reporte1_1!AA160="","",Reporte1_1!AA160) -> 298.67
A17: =IF(Reporte1_1!A168="","",Reporte1_1!A168) -> SCH-186UI | B17: =IF(Reporte1_1!C168="","",Reporte1_1!C168) -> 45950 | C17: PEC | D17: =IF(Reporte1_1!G168="","",Reporte1_1!G168) -> 5 | E17: =IF(Reporte1_1!H168="","",Reporte1_1!H168) -> 2445 | F17: =IF(Reporte1_1!I168="","",Reporte1_1!I168) -> 1956 | G17: =IF(Reporte1_1!J168="","",Reporte1_1!J168) -> 489 | H17: =IF(Reporte1_1!K168="","",Reporte1_1!K168) -> 1173 | I17: =IF(Reporte1_1!L168="","",Reporte1_1!L168) -> 20 | J17: =IF(Reporte1_1!M168="","",Reporte1_1!M168) -> 600 | K17: =IF(Reporte1_1!V168="","",Reporte1_1!V168) -> 334 | L17: =IF(Reporte1_1!Q168="","",Reporte1_1!Q168) -> 23.7 | M17: =IF(Reporte1_1!R168="","",Reporte1_1!R168) -> 63 | N17: =IF(Reporte1_1!S168="","",Reporte1_1!S168) -> 0 | O17: =IF(Reporte1_1!T168="","",Reporte1_1!T168) -> 0 | P17: =IF(Reporte1_1!U168="","",Reporte1_1!U168) -> 140 | Q17: =IF(Reporte1_1!N168="","",Reporte1_1!N168) -> RC4000 CR-CT|RC4000 CR-CT|RC4000 CR-CT|RC4000 CR-CT|D20|D20 | R17: =IF(Reporte1_1!X168="","",Reporte1_1!X168) -> 449 | S17: =IF(Reporte1_1!AA168="","",Reporte1_1!AA168) -> 1980.339
A18: =IF(Reporte1_1!A185="","",Reporte1_1!A185) -> SCHAC-353HI | B18: =IF(Reporte1_1!C185="","",Reporte1_1!C185) -> 45952 | C18: PEC | D18: =IF(Reporte1_1!G185="","",Reporte1_1!G185) -> 5 | E18: =IF(Reporte1_1!H185="","",Reporte1_1!H185) -> 2345 | F18: =IF(Reporte1_1!I185="","",Reporte1_1!I185) -> 141 | G18: =IF(Reporte1_1!J185="","",Reporte1_1!J185) -> 2204 | H18: =IF(Reporte1_1!K185="","",Reporte1_1!K185) -> 1.13 | I18: =IF(Reporte1_1!L185="","",Reporte1_1!L185) -> 93.99 | J18: =IF(Reporte1_1!M185="","",Reporte1_1!M185) -> 8 | K18: =IF(Reporte1_1!V185="","",Reporte1_1!V185) -> 1571 | L18: =IF(Reporte1_1!Q185="","",Reporte1_1!Q185) -> 27.8 | M18: =IF(Reporte1_1!R185="","",Reporte1_1!R185) -> 50 | N18: =IF(Reporte1_1!S185="","",Reporte1_1!S185) -> 0 | O18: =IF(Reporte1_1!T185="","",Reporte1_1!T185) -> 0 | P18: =IF(Reporte1_1!U185="","",Reporte1_1!U185) -> 120 | Q18: =IF(Reporte1_1!N185="","",Reporte1_1!N185) -> WD-3000|WD-3000|WD-3000|WD-3000 | R18: =IF(Reporte1_1!X185="","",Reporte1_1!X185) -> 466 | S18: =IF(Reporte1_1!AA185="","",Reporte1_1!AA185) -> 142.754
A19: =IF(Reporte1_1!A128="","",Reporte1_1!A128) -> SCHH-218HS | B19: =IF(Reporte1_1!C128="","",Reporte1_1!C128) -> 45950 | C19: PEC | D19: =IF(Reporte1_1!G128="","",Reporte1_1!G128) -> 2 | E19: =IF(Reporte1_1!H128="","",Reporte1_1!H128) -> 2147 | F19: =IF(Reporte1_1!I128="","",Reporte1_1!I128) -> 107 | G19: =IF(Reporte1_1!J128="","",Reporte1_1!J128) -> 2040 | H19: =IF(Reporte1_1!K128="","",Reporte1_1!K128) -> 16.21 | I19: =IF(Reporte1_1!L128="","",Reporte1_1!L128) -> 95.02 | J19: =IF(Reporte1_1!M128="","",Reporte1_1!M128) -> 151 | K19: =IF(Reporte1_1!V128="","",Reporte1_1!V128) -> 361 | L19: =IF(Reporte1_1!Q128="","",Reporte1_1!Q128) -> 20.5 | M19: =IF(Reporte1_1!R128="","",Reporte1_1!R128) -> 50 | N19: =IF(Reporte1_1!S128="","",Reporte1_1!S128) -> 0 | O19: =IF(Reporte1_1!T128="","",Reporte1_1!T128) -> 0 | P19: =IF(Reporte1_1!U128="","",Reporte1_1!U128) -> 70 | Q19: =IF(Reporte1_1!N128="","",Reporte1_1!N128) -> WE 5500|WE 5500 | R19: =IF(Reporte1_1!X128="","",Reporte1_1!X128) -> 422 | S19: =IF(Reporte1_1!AA128="","",Reporte1_1!AA128) -> 101.557
A20: =IF(Reporte1_1!A31="","",Reporte1_1!A31) -> SCHAH-404HI | B20: =IF(Reporte1_1!C31="","",Reporte1_1!C31) -> 45928 | C20: PEC | D20: =IF(Reporte1_1!G31="","",Reporte1_1!G31) -> 5 | E20: =IF(Reporte1_1!H31="","",Reporte1_1!H31) -> 2130 | F20: =IF(Reporte1_1!I31="","",Reporte1_1!I31) -> 170 | G20: =IF(Reporte1_1!J31="","",Reporte1_1!J31) -> 1960 | H20: =IF(Reporte1_1!K31="","",Reporte1_1!K31) -> 1.36 | I20: =IF(Reporte1_1!L31="","",Reporte1_1!L31) -> 92.02 | J20: =IF(Reporte1_1!M31="","",Reporte1_1!M31) -> 8 | K20: =IF(Reporte1_1!V31="","",Reporte1_1!V31) -> 2022 | L20: =IF(Reporte1_1!Q31="","",Reporte1_1!Q31) -> 26.6 | M20: =IF(Reporte1_1!R31="","",Reporte1_1!R31) -> 48 | N20: =IF(Reporte1_1!S31="","",Reporte1_1!S31) -> 0 | O20: =IF(Reporte1_1!T31="","",Reporte1_1!T31) -> 0 | P20: =IF(Reporte1_1!U31="","",Reporte1_1!U31) -> 100 | Q20: =IF(Reporte1_1!N31="","",Reporte1_1!N31) -> E3000 SSD|E3000 SSD|E3000 SSD | R20: =IF(Reporte1_1!X31="","",Reporte1_1!X31) -> 385 | S20: =IF(Reporte1_1!AA31="","",Reporte1_1!AA31) -> 172.115
A21: =IF(Reporte1_1!A258="","",Reporte1_1!A258) -> SCHP-181UI | B21: =IF(Reporte1_1!C258="","",Reporte1_1!C258) -> 45947 | C21: PEC | D21: =IF(Reporte1_1!G258="","",Reporte1_1!G258) -> 5 | E21: =IF(Reporte1_1!H258="","",Reporte1_1!H258) -> 2109 | F21: =IF(Reporte1_1!I258="","",Reporte1_1!I258) -> 295 | G21: =IF(Reporte1_1!J258="","",Reporte1_1!J258) -> 1814 | H21: =IF(Reporte1_1!K258="","",Reporte1_1!K258) -> 59.89 | I21: =IF(Reporte1_1!L258="","",Reporte1_1!L258) -> 86.01 | J21: =IF(Reporte1_1!M258="","",Reporte1_1!M258) -> 203 | K21: =IF(Reporte1_1!V258="","",Reporte1_1!V258) -> 163 | L21: =IF(Reporte1_1!Q258="","",Reporte1_1!Q258) -> 24.1 | M21: =IF(Reporte1_1!R258="","",Reporte1_1!R258) -> 59 | N21: =IF(Reporte1_1!S258="","",Reporte1_1!S258) -> 0 | O21: =IF(Reporte1_1!T258="","",Reporte1_1!T258) -> 0 | P21: =IF(Reporte1_1!U258="","",Reporte1_1!U258) -> 90 | Q21: =IF(Reporte1_1!N258="","",Reporte1_1!N258) -> SF-2700|SF-2700|SF-2700|SF-2700 | R21: =IF(Reporte1_1!X258="","",Reporte1_1!X258) -> 472 | S21: =IF(Reporte1_1!AA258="","",Reporte1_1!AA258) -> 298.671
A22: =IF(Reporte1_1!A53="","",Reporte1_1!A53) -> SCH-050UI | B22: =IF(Reporte1_1!C53="","",Reporte1_1!C53) -> 45951 | C22: PEC | D22: =IF(Reporte1_1!G53="","",Reporte1_1!G53) -> 5 | E22: =IF(Reporte1_1!H53="","",Reporte1_1!H53) -> 2012 | F22: =IF(Reporte1_1!I53="","",Reporte1_1!I53) -> 96 | G22: =IF(Reporte1_1!J53="","",Reporte1_1!J53) -> 1916 | H22: =IF(Reporte1_1!K53="","",Reporte1_1!K53) -> 14.88 | I22: =IF(Reporte1_1!L53="","",Reporte1_1!L53) -> 95.23 | J22: =IF(Reporte1_1!M53="","",Reporte1_1!M53) -> 155 | K22: =IF(Reporte1_1!V53="","",Reporte1_1!V53) -> 1427 | L22: =IF(Reporte1_1!Q53="","",Reporte1_1!Q53) -> 24.3 | M22: =IF(Reporte1_1!R53="","",Reporte1_1!R53) -> 62 | N22: =IF(Reporte1_1!S53="","",Reporte1_1!S53) -> 0 | O22: =IF(Reporte1_1!T53="","",Reporte1_1!T53) -> 0 | P22: =IF(Reporte1_1!U53="","",Reporte1_1!U53) -> 150 | Q22: =IF(Reporte1_1!N53="","",Reporte1_1!N53) -> NH2100M|NH2100M|NH2100M | R22: =IF(Reporte1_1!X53="","",Reporte1_1!X53) -> 438 | S22: =IF(Reporte1_1!AA53="","",Reporte1_1!AA53) -> 97.194
A23: =IF(Reporte1_1!A134="","",Reporte1_1!A134) -> SCHH-239HS | B23: =IF(Reporte1_1!C134="","",Reporte1_1!C134) -> 45947 | C23: PEC | D23: =IF(Reporte1_1!G134="","",Reporte1_1!G134) -> 6 | E23: =IF(Reporte1_1!H134="","",Reporte1_1!H134) -> 1888 | F23: =IF(Reporte1_1!I134="","",Reporte1_1!I134) -> 113 | G23: =IF(Reporte1_1!J134="","",Reporte1_1!J134) -> 1775 | H23: =IF(Reporte1_1!K134="","",Reporte1_1!K134) -> 32.66 | I23: =IF(Reporte1_1!L134="","",Reporte1_1!L134) -> 94.02 | J23: =IF(Reporte1_1!M134="","",Reporte1_1!M134) -> 289 | K23: =IF(Reporte1_1!V134="","",Reporte1_1!V134) -> 1383 | L23: =IF(Reporte1_1!Q134="","",Reporte1_1!Q134) -> 24.3 | M23: =IF(Reporte1_1!R134="","",Reporte1_1!R134) -> 51 | N23: =IF(Reporte1_1!S134="","",Reporte1_1!S134) -> 0 | O23: =IF(Reporte1_1!T134="","",Reporte1_1!T134) -> 0 | P23: =IF(Reporte1_1!U134="","",Reporte1_1!U134) -> 50 | Q23: =IF(Reporte1_1!N134="","",Reporte1_1!N134) -> WD-3000|WD-3000|WD-3000|WD-3000 | R23: =IF(Reporte1_1!X134="","",Reporte1_1!X134) -> 394 | S23: =IF(Reporte1_1!AA134="","",Reporte1_1!AA134) -> 107.252
A24: =IF(Reporte1_1!A199="","",Reporte1_1!A199) -> SCHAE-373HUI | B24: =IF(Reporte1_1!C199="","",Reporte1_1!C199) -> 45935 | C24: PEC | D24: =IF(Reporte1_1!G199="","",Reporte1_1!G199) -> 2 | E24: =IF(Reporte1_1!H199="","",Reporte1_1!H199) -> 1852 | F24: =IF(Reporte1_1!I199="","",Reporte1_1!I199) -> 148 | G24: =IF(Reporte1_1!J199="","",Reporte1_1!J199) -> 1704 | H24: =IF(Reporte1_1!K199="","",Reporte1_1!K199) -> 22.94 | I24: =IF(Reporte1_1!L199="","",Reporte1_1!L199) -> 92.01 | J24: =IF(Reporte1_1!M199="","",Reporte1_1!M199) -> 155 | K24: =IF(Reporte1_1!V199="","",Reporte1_1!V199) -> 841 | L24: =IF(Reporte1_1!Q199="","",Reporte1_1!Q199) -> 17.3 | M24: =IF(Reporte1_1!R199="","",Reporte1_1!R199) -> 52 | N24: =IF(Reporte1_1!S199="","",Reporte1_1!S199) -> 0 | O24: =IF(Reporte1_1!T199="","",Reporte1_1!T199) -> 0 | P24: =IF(Reporte1_1!U199="","",Reporte1_1!U199) -> 110 | Q24: =IF(Reporte1_1!N199="","",Reporte1_1!N199) -> P23|P23 | R24: =IF(Reporte1_1!X199="","",Reporte1_1!X199) -> 476 | S24: =IF(Reporte1_1!AA199="","",Reporte1_1!AA199) -> 149.842
A25: =IF(Reporte1_1!A60="","",Reporte1_1!A60) -> SCH-127HS | B25: =IF(Reporte1_1!C60="","",Reporte1_1!C60) -> 45942 | C25: PEC | D25: =IF(Reporte1_1!G60="","",Reporte1_1!G60) -> 5 | E25: =IF(Reporte1_1!H60="","",Reporte1_1!H60) -> 1838 | F25: =IF(Reporte1_1!I60="","",Reporte1_1!I60) -> 441 | G25: =IF(Reporte1_1!J60="","",Reporte1_1!J60) -> 1397 | H25: =IF(Reporte1_1!K60="","",Reporte1_1!K60) -> 66.59 | I25: =IF(Reporte1_1!L60="","",Reporte1_1!L60) -> 76.01 | J25: =IF(Reporte1_1!M60="","",Reporte1_1!M60) -> 151 | K25: =IF(Reporte1_1!V60="","",Reporte1_1!V60) -> 0 | L25: =IF(Reporte1_1!Q60="","",Reporte1_1!Q60) -> 26.1 | M25: =IF(Reporte1_1!R60="","",Reporte1_1!R60) -> 55 | N25: =IF(Reporte1_1!S60="","",Reporte1_1!S60) -> 0 | O25: =IF(Reporte1_1!T60="","",Reporte1_1!T60) -> 0 | P25: =IF(Reporte1_1!U60="","",Reporte1_1!U60) -> 90 | Q25: =IF(Reporte1_1!N60="","",Reporte1_1!N60) -> DN1750|DN1750|DN1750 | R25: =IF(Reporte1_1!X60="","",Reporte1_1!X60) -> 434 | S25: =IF(Reporte1_1!AA60="","",Reporte1_1!AA60) -> 446.487
A26: =IF(Reporte1_1!A159="","",Reporte1_1!A159) -> SCH-123UI | B26: =IF(Reporte1_1!C159="","",Reporte1_1!C159) -> 45944 | C26: PEC | D26: =IF(Reporte1_1!G159="","",Reporte1_1!G159) -> 4 | E26: =IF(Reporte1_1!H159="","",Reporte1_1!H159) -> 1711.3 | F26: =IF(Reporte1_1!I159="","",Reporte1_1!I159) -> 821.3 | G26: =IF(Reporte1_1!J159="","",Reporte1_1!J159) -> 890 | H26: =IF(Reporte1_1!K159="","",Reporte1_1!K159) -> 127.26 | I26: =IF(Reporte1_1!L159="","",Reporte1_1!L159) -> 52.01 | J26: =IF(Reporte1_1!M159="","",Reporte1_1!M159) -> 155 | K26: =IF(Reporte1_1!V159="","",Reporte1_1!V159) -> 430 | L26: =IF(Reporte1_1!Q159="","",Reporte1_1!Q159) -> 24 | M26: =IF(Reporte1_1!R159="","",Reporte1_1!R159) -> 64 | N26: =IF(Reporte1_1!S159="","",Reporte1_1!S159) -> 0 | O26: =IF(Reporte1_1!T159="","",Reporte1_1!T159) -> 0 | P26: =IF(Reporte1_1!U159="","",Reporte1_1!U159) -> 100 | Q26: =IF(Reporte1_1!N159="","",Reporte1_1!N159) -> E3000 SSD|E3000 SSD|E3000 SSD | R26: =IF(Reporte1_1!X159="","",Reporte1_1!X159) -> 473 | S26: =IF(Reporte1_1!AA159="","",Reporte1_1!AA159) -> 831.52
A27: =IF(Reporte1_1!A144="","",Reporte1_1!A144) -> SCHV-227HS | B27: =IF(Reporte1_1!C144="","",Reporte1_1!C144) -> 45941 | C27: PEC | D27: =IF(Reporte1_1!G144="","",Reporte1_1!G144) -> 4 | E27: =IF(Reporte1_1!H144="","",Reporte1_1!H144) -> 1705 | F27: =IF(Reporte1_1!I144="","",Reporte1_1!I144) -> 290 | G27: =IF(Reporte1_1!J144="","",Reporte1_1!J144) -> 1415 | H27: =IF(Reporte1_1!K144="","",Reporte1_1!K144) -> 2.32 | I27: =IF(Reporte1_1!L144="","",Reporte1_1!L144) -> 82.99 | J27: =IF(Reporte1_1!M144="","",Reporte1_1!M144) -> 8 | K27: =IF(Reporte1_1!V144="","",Reporte1_1!V144) -> 1191 | L27: =IF(Reporte1_1!Q144="","",Reporte1_1!Q144) -> 24.8 | M27: =IF(Reporte1_1!R144="","",Reporte1_1!R144) -> 52 | N27: =IF(Reporte1_1!S144="","",Reporte1_1!S144) -> 0 | O27: =IF(Reporte1_1!T144="","",Reporte1_1!T144) -> 0 | P27: =IF(Reporte1_1!U144="","",Reporte1_1!U144) -> 36 | Q27: =IF(Reporte1_1!N144="","",Reporte1_1!N144) -> WD-3000|WD-3000|WD-3000|WD-3000 | R27: =IF(Reporte1_1!X144="","",Reporte1_1!X144) -> 409 | S27: =IF(Reporte1_1!AA144="","",Reporte1_1!AA144) -> 275.248
A28: =IF(Reporte1_1!A111="","",Reporte1_1!A111) -> SCHAM-452HI | B28: =IF(Reporte1_1!C111="","",Reporte1_1!C111) -> 45940 | C28: PEC | D28: =IF(Reporte1_1!G111="","",Reporte1_1!G111) -> 4 | E28: =IF(Reporte1_1!H111="","",Reporte1_1!H111) -> 1704 | F28: =IF(Reporte1_1!I111="","",Reporte1_1!I111) -> 204 | G28: =IF(Reporte1_1!J111="","",Reporte1_1!J111) -> 1500 | H28: =IF(Reporte1_1!K111="","",Reporte1_1!K111) -> 68.96 | I28: =IF(Reporte1_1!L111="","",Reporte1_1!L111) -> 88.03 | J28: =IF(Reporte1_1!M111="","",Reporte1_1!M111) -> 338 | K28: =IF(Reporte1_1!V111="","",Reporte1_1!V111) -> 1410 | L28: =IF(Reporte1_1!Q111="","",Reporte1_1!Q111) -> 23.9 | M28: =IF(Reporte1_1!R111="","",Reporte1_1!R111) -> 42 | N28: =IF(Reporte1_1!S111="","",Reporte1_1!S111) -> 0 | O28: =IF(Reporte1_1!T111="","",Reporte1_1!T111) -> 0 | P28: =IF(Reporte1_1!U111="","",Reporte1_1!U111) -> 80 | Q28: =IF(Reporte1_1!N111="","",Reporte1_1!N111) -> FLEX47|FLEX47 | R28: =IF(Reporte1_1!X111="","",Reporte1_1!X111) -> 336 | S28: =IF(Reporte1_1!AA111="","",Reporte1_1!AA111) -> 193.623
